[2022-12-31T20:36:23.494+0000] {taskinstance.py:1165} INFO - Dependencies all met for <TaskInstance: dpt_cosmetic.test manual__2022-12-31T20:36:19.685783+00:00 [queued]>
[2022-12-31T20:36:23.570+0000] {taskinstance.py:1165} INFO - Dependencies all met for <TaskInstance: dpt_cosmetic.test manual__2022-12-31T20:36:19.685783+00:00 [queued]>
[2022-12-31T20:36:23.572+0000] {taskinstance.py:1362} INFO - 
--------------------------------------------------------------------------------
[2022-12-31T20:36:23.574+0000] {taskinstance.py:1363} INFO - Starting attempt 1 of 1
[2022-12-31T20:36:23.575+0000] {taskinstance.py:1364} INFO - 
--------------------------------------------------------------------------------
[2022-12-31T20:36:23.714+0000] {taskinstance.py:1383} INFO - Executing <Task(PythonOperator): test> on 2022-12-31 20:36:19.685783+00:00
[2022-12-31T20:36:23.739+0000] {standard_task_runner.py:55} INFO - Started process 58 to run task
[2022-12-31T20:36:23.776+0000] {standard_task_runner.py:82} INFO - Running: ['***', 'tasks', 'run', 'dpt_cosmetic', 'test', 'manual__2022-12-31T20:36:19.685783+00:00', '--job-id', '11', '--raw', '--subdir', 'DAGS_FOLDER/main.py', '--cfg-path', '/tmp/tmpuhea51ka']
[2022-12-31T20:36:23.780+0000] {standard_task_runner.py:83} INFO - Job 11: Subtask test
[2022-12-31T20:36:24.203+0000] {task_command.py:376} INFO - Running <TaskInstance: dpt_cosmetic.test manual__2022-12-31T20:36:19.685783+00:00 [running]> on host 19ecae0451dd
[2022-12-31T20:36:24.612+0000] {taskinstance.py:1592} INFO - Exporting the following env vars:
AIRFLOW_CTX_DAG_OWNER=***
AIRFLOW_CTX_DAG_ID=dpt_cosmetic
AIRFLOW_CTX_TASK_ID=test
AIRFLOW_CTX_EXECUTION_DATE=2022-12-31T20:36:19.685783+00:00
AIRFLOW_CTX_TRY_NUMBER=1
AIRFLOW_CTX_DAG_RUN_ID=manual__2022-12-31T20:36:19.685783+00:00
[2022-12-31T20:36:24.666+0000] {base.py:71} INFO - Using connection ID 'mongodb' for task execution.
[2022-12-31T20:36:24.769+0000] {taskinstance.py:1851} ERROR - Task failed with exception
Traceback (most recent call last):
  File "/home/airflow/.local/lib/python3.7/site-packages/airflow/operators/python.py", line 175, in execute
    return_value = self.execute_callable()
  File "/home/airflow/.local/lib/python3.7/site-packages/airflow/operators/python.py", line 193, in execute_callable
    return self.python_callable(*self.op_args, **self.op_kwargs)
  File "/opt/airflow/dags/main.py", line 8, in print_
    sources=get_sources()
  File "/opt/airflow/dags/utilties/connection.py", line 38, in get_sources
    mongo_collection=os.environ.get("SOURCES_MONGO_COLLECTION"),
  File "/home/airflow/.local/lib/python3.7/site-packages/airflow/providers/mongo/hooks/mongo.py", line 114, in get_collection
    return mongo_conn.get_database(mongo_db).get_collection(mongo_collection)
  File "/home/airflow/.local/lib/python3.7/site-packages/pymongo/database.py", line 362, in get_collection
    self, name, False, codec_options, read_preference, write_concern, read_concern
  File "/home/airflow/.local/lib/python3.7/site-packages/pymongo/collection.py", line 177, in __init__
    raise TypeError("name must be an instance " "of %s" % (string_type.__name__,))
TypeError: name must be an instance of str
[2022-12-31T20:36:24.899+0000] {taskinstance.py:1406} INFO - Marking task as FAILED. dag_id=dpt_cosmetic, task_id=test, execution_date=20221231T203619, start_date=20221231T203623, end_date=20221231T203624
[2022-12-31T20:36:24.976+0000] {standard_task_runner.py:105} ERROR - Failed to execute job 11 for task test (name must be an instance of str; 58)
[2022-12-31T20:36:25.059+0000] {local_task_job.py:164} INFO - Task exited with return code 1
[2022-12-31T20:36:25.225+0000] {local_task_job.py:273} INFO - 0 downstream tasks scheduled from follow-on schedule check
