[2023-01-02T15:30:49.486+0000] {taskinstance.py:1165} INFO - Dependencies all met for <TaskInstance: gcs.gcs_test manual__2023-01-02T15:30:44.990664+00:00 [queued]>
[2023-01-02T15:30:49.526+0000] {taskinstance.py:1165} INFO - Dependencies all met for <TaskInstance: gcs.gcs_test manual__2023-01-02T15:30:44.990664+00:00 [queued]>
[2023-01-02T15:30:49.527+0000] {taskinstance.py:1362} INFO - 
--------------------------------------------------------------------------------
[2023-01-02T15:30:49.529+0000] {taskinstance.py:1363} INFO - Starting attempt 1 of 1
[2023-01-02T15:30:49.531+0000] {taskinstance.py:1364} INFO - 
--------------------------------------------------------------------------------
[2023-01-02T15:30:49.595+0000] {taskinstance.py:1383} INFO - Executing <Task(PythonOperator): gcs_test> on 2023-01-02 15:30:44.990664+00:00
[2023-01-02T15:30:49.613+0000] {standard_task_runner.py:55} INFO - Started process 60 to run task
[2023-01-02T15:30:49.625+0000] {standard_task_runner.py:82} INFO - Running: ['***', 'tasks', 'run', 'gcs', 'gcs_test', 'manual__2023-01-02T15:30:44.990664+00:00', '--job-id', '203', '--raw', '--subdir', 'DAGS_FOLDER/gcs.py', '--cfg-path', '/tmp/tmpp510iuzz']
[2023-01-02T15:30:49.632+0000] {standard_task_runner.py:83} INFO - Job 203: Subtask gcs_test
[2023-01-02T15:30:49.880+0000] {task_command.py:376} INFO - Running <TaskInstance: gcs.gcs_test manual__2023-01-02T15:30:44.990664+00:00 [running]> on host 703acec1b71e
[2023-01-02T15:30:50.180+0000] {taskinstance.py:1592} INFO - Exporting the following env vars:
AIRFLOW_CTX_DAG_OWNER=***
AIRFLOW_CTX_DAG_ID=gcs
AIRFLOW_CTX_TASK_ID=gcs_test
AIRFLOW_CTX_EXECUTION_DATE=2023-01-02T15:30:44.990664+00:00
AIRFLOW_CTX_TRY_NUMBER=1
AIRFLOW_CTX_DAG_RUN_ID=manual__2023-01-02T15:30:44.990664+00:00
[2023-01-02T15:30:50.183+0000] {taskinstance.py:1851} ERROR - Task failed with exception
Traceback (most recent call last):
  File "/home/airflow/.local/lib/python3.7/site-packages/airflow/operators/python.py", line 175, in execute
    return_value = self.execute_callable()
  File "/home/airflow/.local/lib/python3.7/site-packages/airflow/operators/python.py", line 193, in execute_callable
    return self.python_callable(*self.op_args, **self.op_kwargs)
  File "/opt/airflow/dags/gcs.py", line 13, in upload_to_gcs
    google_cloud_storage_conn_id="my_google"
TypeError: __init__() got an unexpected keyword argument 'google_cloud_storage_conn_id'
[2023-01-02T15:30:50.229+0000] {taskinstance.py:1406} INFO - Marking task as FAILED. dag_id=gcs, task_id=gcs_test, execution_date=20230102T153044, start_date=20230102T153049, end_date=20230102T153050
[2023-01-02T15:30:50.276+0000] {standard_task_runner.py:105} ERROR - Failed to execute job 203 for task gcs_test (__init__() got an unexpected keyword argument 'google_cloud_storage_conn_id'; 60)
[2023-01-02T15:30:50.322+0000] {local_task_job.py:164} INFO - Task exited with return code 1
[2023-01-02T15:30:50.406+0000] {local_task_job.py:273} INFO - 0 downstream tasks scheduled from follow-on schedule check
