[2023-01-06T01:21:37.914+0000] {taskinstance.py:1165} INFO - Dependencies all met for <TaskInstance: dpt_cosmetic.transaction_01.check_table manual__2023-01-06T01:21:34.810654+00:00 [queued]>
[2023-01-06T01:21:37.927+0000] {taskinstance.py:1165} INFO - Dependencies all met for <TaskInstance: dpt_cosmetic.transaction_01.check_table manual__2023-01-06T01:21:34.810654+00:00 [queued]>
[2023-01-06T01:21:37.927+0000] {taskinstance.py:1362} INFO - 
--------------------------------------------------------------------------------
[2023-01-06T01:21:37.928+0000] {taskinstance.py:1363} INFO - Starting attempt 1 of 1
[2023-01-06T01:21:37.928+0000] {taskinstance.py:1364} INFO - 
--------------------------------------------------------------------------------
[2023-01-06T01:21:37.958+0000] {taskinstance.py:1383} INFO - Executing <Task(BranchPythonOperator): transaction_01.check_table> on 2023-01-06 01:21:34.810654+00:00
[2023-01-06T01:21:37.964+0000] {standard_task_runner.py:55} INFO - Started process 70 to run task
[2023-01-06T01:21:37.970+0000] {standard_task_runner.py:82} INFO - Running: ['***', 'tasks', 'run', 'dpt_cosmetic', 'transaction_01.check_table', 'manual__2023-01-06T01:21:34.810654+00:00', '--job-id', '336', '--raw', '--subdir', 'DAGS_FOLDER/main.py', '--cfg-path', '/tmp/tmp6rihbtn6']
[2023-01-06T01:21:37.973+0000] {standard_task_runner.py:83} INFO - Job 336: Subtask transaction_01.check_table
[2023-01-06T01:21:38.086+0000] {task_command.py:376} INFO - Running <TaskInstance: dpt_cosmetic.transaction_01.check_table manual__2023-01-06T01:21:34.810654+00:00 [running]> on host fdf4acf1d8ed
[2023-01-06T01:21:38.210+0000] {taskinstance.py:1592} INFO - Exporting the following env vars:
AIRFLOW_CTX_DAG_OWNER=***
AIRFLOW_CTX_DAG_ID=dpt_cosmetic
AIRFLOW_CTX_TASK_ID=transaction_01.check_table
AIRFLOW_CTX_EXECUTION_DATE=2023-01-06T01:21:34.810654+00:00
AIRFLOW_CTX_TRY_NUMBER=1
AIRFLOW_CTX_DAG_RUN_ID=manual__2023-01-06T01:21:34.810654+00:00
[2023-01-06T01:21:38.868+0000] {python.py:177} INFO - Done. Returned value was: task_groups.create_table
[2023-01-06T01:21:38.913+0000] {taskinstance.py:1851} ERROR - Task failed with exception
Traceback (most recent call last):
  File "/home/airflow/.local/lib/python3.7/site-packages/airflow/operators/python.py", line 225, in execute
    f"Branch callable must return valid task_ids. Invalid tasks found: {invalid_task_ids}"
airflow.exceptions.AirflowException: Branch callable must return valid task_ids. Invalid tasks found: {'task_groups.create_table'}
[2023-01-06T01:21:38.929+0000] {taskinstance.py:1406} INFO - Marking task as FAILED. dag_id=dpt_cosmetic, task_id=transaction_01.check_table, execution_date=20230106T012134, start_date=20230106T012137, end_date=20230106T012138
[2023-01-06T01:21:38.982+0000] {standard_task_runner.py:105} ERROR - Failed to execute job 336 for task transaction_01.check_table (Branch callable must return valid task_ids. Invalid tasks found: {'task_groups.create_table'}; 70)
[2023-01-06T01:21:39.027+0000] {local_task_job.py:164} INFO - Task exited with return code 1
[2023-01-06T01:21:39.161+0000] {local_task_job.py:273} INFO - 0 downstream tasks scheduled from follow-on schedule check
