[2023-01-05T22:22:15.573+0000] {taskinstance.py:1165} INFO - Dependencies all met for <TaskInstance: dpt_cosmetic.create_dataset manual__2023-01-05T22:22:08.647407+00:00 [queued]>
[2023-01-05T22:22:15.618+0000] {taskinstance.py:1165} INFO - Dependencies all met for <TaskInstance: dpt_cosmetic.create_dataset manual__2023-01-05T22:22:08.647407+00:00 [queued]>
[2023-01-05T22:22:15.620+0000] {taskinstance.py:1362} INFO - 
--------------------------------------------------------------------------------
[2023-01-05T22:22:15.621+0000] {taskinstance.py:1363} INFO - Starting attempt 1 of 1
[2023-01-05T22:22:15.623+0000] {taskinstance.py:1364} INFO - 
--------------------------------------------------------------------------------
[2023-01-05T22:22:15.698+0000] {taskinstance.py:1383} INFO - Executing <Task(GCSToBigQueryOperator): create_dataset> on 2023-01-05 22:22:08.647407+00:00
[2023-01-05T22:22:15.715+0000] {standard_task_runner.py:55} INFO - Started process 120 to run task
[2023-01-05T22:22:15.734+0000] {standard_task_runner.py:82} INFO - Running: ['***', 'tasks', 'run', 'dpt_cosmetic', 'create_dataset', 'manual__2023-01-05T22:22:08.647407+00:00', '--job-id', '319', '--raw', '--subdir', 'DAGS_FOLDER/main.py', '--cfg-path', '/tmp/tmpi3wqg18d']
[2023-01-05T22:22:15.743+0000] {standard_task_runner.py:83} INFO - Job 319: Subtask create_dataset
[2023-01-05T22:22:16.041+0000] {task_command.py:376} INFO - Running <TaskInstance: dpt_cosmetic.create_dataset manual__2023-01-05T22:22:08.647407+00:00 [running]> on host fdf4acf1d8ed
[2023-01-05T22:22:16.370+0000] {taskinstance.py:1592} INFO - Exporting the following env vars:
AIRFLOW_CTX_DAG_OWNER=***
AIRFLOW_CTX_DAG_ID=dpt_cosmetic
AIRFLOW_CTX_TASK_ID=create_dataset
AIRFLOW_CTX_EXECUTION_DATE=2023-01-05T22:22:08.647407+00:00
AIRFLOW_CTX_TRY_NUMBER=1
AIRFLOW_CTX_DAG_RUN_ID=manual__2023-01-05T22:22:08.647407+00:00
[2023-01-05T22:22:16.375+0000] {connection.py:429} ERROR - Unable to retrieve connection from secrets backend (EnvironmentVariablesBackend). Checking subsequent secrets backend.
Traceback (most recent call last):
  File "/home/airflow/.local/lib/python3.7/site-packages/airflow/models/connection.py", line 422, in get_connection_from_secrets
    conn = secrets_backend.get_connection(conn_id=conn_id)
  File "/home/airflow/.local/lib/python3.7/site-packages/airflow/secrets/base_secrets.py", line 115, in get_connection
    return self.deserialize_connection(conn_id=conn_id, value=value)
  File "/home/airflow/.local/lib/python3.7/site-packages/airflow/secrets/base_secrets.py", line 67, in deserialize_connection
    return Connection.from_json(conn_id=conn_id, value=value)
  File "/home/airflow/.local/lib/python3.7/site-packages/airflow/models/connection.py", line 449, in from_json
    return Connection(conn_id=conn_id, **kwargs)
TypeError: __init__() got an unexpected keyword argument 'key_path'
[2023-01-05T22:22:16.412+0000] {base.py:71} INFO - Using connection ID 'google_cloud_default' for task execution.
[2023-01-05T22:22:16.446+0000] {bigquery.py:2842} INFO - Project not included in destination_project_dataset_table: cosmetic.user; using project "my-kubeflow-370515"
[2023-01-05T22:22:16.451+0000] {bigquery.py:1554} INFO - Inserting job ***_1672957336448886_9d4da99af616bc06a3e3c1deb3600afc
[2023-01-05T22:22:19.366+0000] {taskinstance.py:1406} INFO - Marking task as SUCCESS. dag_id=dpt_cosmetic, task_id=create_dataset, execution_date=20230105T222208, start_date=20230105T222215, end_date=20230105T222219
[2023-01-05T22:22:19.454+0000] {local_task_job.py:164} INFO - Task exited with return code 0
[2023-01-05T22:22:19.553+0000] {local_task_job.py:273} INFO - 0 downstream tasks scheduled from follow-on schedule check
