[2023-01-01T00:15:10.947+0000] {taskinstance.py:1165} INFO - Dependencies all met for <TaskInstance: dpt_cosmetic.user.extract manual__2023-01-01T00:14:57.797576+00:00 [queued]>
[2023-01-01T00:15:11.024+0000] {taskinstance.py:1165} INFO - Dependencies all met for <TaskInstance: dpt_cosmetic.user.extract manual__2023-01-01T00:14:57.797576+00:00 [queued]>
[2023-01-01T00:15:11.026+0000] {taskinstance.py:1362} INFO - 
--------------------------------------------------------------------------------
[2023-01-01T00:15:11.028+0000] {taskinstance.py:1363} INFO - Starting attempt 1 of 1
[2023-01-01T00:15:11.030+0000] {taskinstance.py:1364} INFO - 
--------------------------------------------------------------------------------
[2023-01-01T00:15:11.159+0000] {taskinstance.py:1383} INFO - Executing <Task(ExtractOperator): user.extract> on 2023-01-01 00:14:57.797576+00:00
[2023-01-01T00:15:11.178+0000] {standard_task_runner.py:55} INFO - Started process 554 to run task
[2023-01-01T00:15:11.198+0000] {standard_task_runner.py:82} INFO - Running: ['***', 'tasks', 'run', 'dpt_cosmetic', 'user.extract', 'manual__2023-01-01T00:14:57.797576+00:00', '--job-id', '90', '--raw', '--subdir', 'DAGS_FOLDER/main.py', '--cfg-path', '/tmp/tmpdw7gp4oh']
[2023-01-01T00:15:11.202+0000] {standard_task_runner.py:83} INFO - Job 90: Subtask user.extract
[2023-01-01T00:15:11.593+0000] {task_command.py:376} INFO - Running <TaskInstance: dpt_cosmetic.user.extract manual__2023-01-01T00:14:57.797576+00:00 [running]> on host 6bd76effbc07
[2023-01-01T00:15:12.036+0000] {taskinstance.py:1592} INFO - Exporting the following env vars:
AIRFLOW_CTX_DAG_OWNER=***
AIRFLOW_CTX_DAG_ID=dpt_cosmetic
AIRFLOW_CTX_TASK_ID=user.extract
AIRFLOW_CTX_EXECUTION_DATE=2023-01-01T00:14:57.797576+00:00
AIRFLOW_CTX_TRY_NUMBER=1
AIRFLOW_CTX_DAG_RUN_ID=manual__2023-01-01T00:14:57.797576+00:00
[2023-01-01T00:15:12.039+0000] {taskinstance.py:1851} ERROR - Task failed with exception
Traceback (most recent call last):
  File "/opt/airflow/dags/utilties/extract_operator.py", line 18, in execute
    query=query
TypeError: find() takes no keyword arguments
[2023-01-01T00:15:12.092+0000] {taskinstance.py:1406} INFO - Marking task as FAILED. dag_id=dpt_cosmetic, task_id=user.extract, execution_date=20230101T001457, start_date=20230101T001510, end_date=20230101T001512
[2023-01-01T00:15:12.149+0000] {standard_task_runner.py:105} ERROR - Failed to execute job 90 for task user.extract (find() takes no keyword arguments; 554)
[2023-01-01T00:15:12.214+0000] {local_task_job.py:164} INFO - Task exited with return code 1
[2023-01-01T00:15:12.369+0000] {local_task_job.py:273} INFO - 0 downstream tasks scheduled from follow-on schedule check
