[2023-01-06T01:17:37.639+0000] {taskinstance.py:1165} INFO - Dependencies all met for <TaskInstance: dpt_cosmetic.user_01.check_table manual__2023-01-06T01:17:34.657688+00:00 [queued]>
[2023-01-06T01:17:37.654+0000] {taskinstance.py:1165} INFO - Dependencies all met for <TaskInstance: dpt_cosmetic.user_01.check_table manual__2023-01-06T01:17:34.657688+00:00 [queued]>
[2023-01-06T01:17:37.655+0000] {taskinstance.py:1362} INFO - 
--------------------------------------------------------------------------------
[2023-01-06T01:17:37.656+0000] {taskinstance.py:1363} INFO - Starting attempt 1 of 1
[2023-01-06T01:17:37.656+0000] {taskinstance.py:1364} INFO - 
--------------------------------------------------------------------------------
[2023-01-06T01:17:37.678+0000] {taskinstance.py:1383} INFO - Executing <Task(BranchPythonOperator): user_01.check_table> on 2023-01-06 01:17:34.657688+00:00
[2023-01-06T01:17:37.687+0000] {standard_task_runner.py:55} INFO - Started process 63 to run task
[2023-01-06T01:17:37.692+0000] {standard_task_runner.py:82} INFO - Running: ['***', 'tasks', 'run', 'dpt_cosmetic', 'user_01.check_table', 'manual__2023-01-06T01:17:34.657688+00:00', '--job-id', '333', '--raw', '--subdir', 'DAGS_FOLDER/main.py', '--cfg-path', '/tmp/tmpql4bhg4q']
[2023-01-06T01:17:37.695+0000] {standard_task_runner.py:83} INFO - Job 333: Subtask user_01.check_table
[2023-01-06T01:17:37.779+0000] {task_command.py:376} INFO - Running <TaskInstance: dpt_cosmetic.user_01.check_table manual__2023-01-06T01:17:34.657688+00:00 [running]> on host fdf4acf1d8ed
[2023-01-06T01:17:37.871+0000] {taskinstance.py:1592} INFO - Exporting the following env vars:
AIRFLOW_CTX_DAG_OWNER=***
AIRFLOW_CTX_DAG_ID=dpt_cosmetic
AIRFLOW_CTX_TASK_ID=user_01.check_table
AIRFLOW_CTX_EXECUTION_DATE=2023-01-06T01:17:34.657688+00:00
AIRFLOW_CTX_TRY_NUMBER=1
AIRFLOW_CTX_DAG_RUN_ID=manual__2023-01-06T01:17:34.657688+00:00
[2023-01-06T01:17:38.358+0000] {python.py:177} INFO - Done. Returned value was: insert_data
[2023-01-06T01:17:38.378+0000] {taskinstance.py:1851} ERROR - Task failed with exception
Traceback (most recent call last):
  File "/home/airflow/.local/lib/python3.7/site-packages/airflow/operators/python.py", line 225, in execute
    f"Branch callable must return valid task_ids. Invalid tasks found: {invalid_task_ids}"
airflow.exceptions.AirflowException: Branch callable must return valid task_ids. Invalid tasks found: {'insert_data'}
[2023-01-06T01:17:38.385+0000] {taskinstance.py:1406} INFO - Marking task as FAILED. dag_id=dpt_cosmetic, task_id=user_01.check_table, execution_date=20230106T011734, start_date=20230106T011737, end_date=20230106T011738
[2023-01-06T01:17:38.408+0000] {standard_task_runner.py:105} ERROR - Failed to execute job 333 for task user_01.check_table (Branch callable must return valid task_ids. Invalid tasks found: {'insert_data'}; 63)
[2023-01-06T01:17:38.427+0000] {local_task_job.py:164} INFO - Task exited with return code 1
[2023-01-06T01:17:38.499+0000] {local_task_job.py:273} INFO - 0 downstream tasks scheduled from follow-on schedule check
