[2023-01-02T16:42:39.848+0000] {taskinstance.py:1165} INFO - Dependencies all met for <TaskInstance: dpt_cosmetic.user.load_to_google_storage manual__2023-01-02T16:42:08.483384+00:00 [queued]>
[2023-01-02T16:42:39.904+0000] {taskinstance.py:1165} INFO - Dependencies all met for <TaskInstance: dpt_cosmetic.user.load_to_google_storage manual__2023-01-02T16:42:08.483384+00:00 [queued]>
[2023-01-02T16:42:39.905+0000] {taskinstance.py:1362} INFO - 
--------------------------------------------------------------------------------
[2023-01-02T16:42:39.907+0000] {taskinstance.py:1363} INFO - Starting attempt 1 of 1
[2023-01-02T16:42:39.909+0000] {taskinstance.py:1364} INFO - 
--------------------------------------------------------------------------------
[2023-01-02T16:42:40.006+0000] {taskinstance.py:1383} INFO - Executing <Task(LocalToStorageOperator): user.load_to_google_storage> on 2023-01-02 16:42:08.483384+00:00
[2023-01-02T16:42:40.023+0000] {standard_task_runner.py:55} INFO - Started process 347 to run task
[2023-01-02T16:42:40.039+0000] {standard_task_runner.py:82} INFO - Running: ['***', 'tasks', 'run', 'dpt_cosmetic', 'user.load_to_google_storage', 'manual__2023-01-02T16:42:08.483384+00:00', '--job-id', '243', '--raw', '--subdir', 'DAGS_FOLDER/main.py', '--cfg-path', '/tmp/tmpam35cq24']
[2023-01-02T16:42:40.041+0000] {standard_task_runner.py:83} INFO - Job 243: Subtask user.load_to_google_storage
[2023-01-02T16:42:41.010+0000] {task_command.py:376} INFO - Running <TaskInstance: dpt_cosmetic.user.load_to_google_storage manual__2023-01-02T16:42:08.483384+00:00 [running]> on host 703acec1b71e
[2023-01-02T16:42:41.377+0000] {taskinstance.py:1592} INFO - Exporting the following env vars:
AIRFLOW_CTX_DAG_OWNER=***
AIRFLOW_CTX_DAG_ID=dpt_cosmetic
AIRFLOW_CTX_TASK_ID=user.load_to_google_storage
AIRFLOW_CTX_EXECUTION_DATE=2023-01-02T16:42:08.483384+00:00
AIRFLOW_CTX_TRY_NUMBER=1
AIRFLOW_CTX_DAG_RUN_ID=manual__2023-01-02T16:42:08.483384+00:00
[2023-01-02T16:42:41.382+0000] {connection.py:429} ERROR - Unable to retrieve connection from secrets backend (EnvironmentVariablesBackend). Checking subsequent secrets backend.
Traceback (most recent call last):
  File "/home/airflow/.local/lib/python3.7/site-packages/airflow/models/connection.py", line 422, in get_connection_from_secrets
    conn = secrets_backend.get_connection(conn_id=conn_id)
  File "/home/airflow/.local/lib/python3.7/site-packages/airflow/secrets/base_secrets.py", line 115, in get_connection
    return self.deserialize_connection(conn_id=conn_id, value=value)
  File "/home/airflow/.local/lib/python3.7/site-packages/airflow/secrets/base_secrets.py", line 67, in deserialize_connection
    return Connection.from_json(conn_id=conn_id, value=value)
  File "/home/airflow/.local/lib/python3.7/site-packages/airflow/models/connection.py", line 449, in from_json
    return Connection(conn_id=conn_id, **kwargs)
TypeError: __init__() got an unexpected keyword argument 'key_path'
[2023-01-02T16:42:41.425+0000] {base.py:71} INFO - Using connection ID 'google_cloud_default' for task execution.
[2023-01-02T16:42:41.475+0000] {taskinstance.py:1851} ERROR - Task failed with exception
Traceback (most recent call last):
  File "/opt/airflow/dags/utilties/operator.py", line 27, in execute
    gcs.upload(self.bucket,self.dest_path,self.local_path)
  File "/home/airflow/.local/lib/python3.7/site-packages/airflow/providers/google/cloud/hooks/gcs.py", line 513, in upload
    partial(blob.upload_from_filename, filename=filename, content_type=mime_type, timeout=timeout)
  File "/home/airflow/.local/lib/python3.7/site-packages/airflow/providers/google/cloud/hooks/gcs.py", line 470, in _call_with_retry
    f()
  File "/home/airflow/.local/lib/python3.7/site-packages/google/cloud/storage/blob.py", line 2720, in upload_from_filename
    with open(filename, "rb") as file_obj:
FileNotFoundError: [Errno 2] No such file or directory: '/opt/airflow/storage/user/2023-01-03'
[2023-01-02T16:42:41.546+0000] {taskinstance.py:1406} INFO - Marking task as FAILED. dag_id=dpt_cosmetic, task_id=user.load_to_google_storage, execution_date=20230102T164208, start_date=20230102T164239, end_date=20230102T164241
[2023-01-02T16:42:41.615+0000] {standard_task_runner.py:105} ERROR - Failed to execute job 243 for task user.load_to_google_storage ([Errno 2] No such file or directory: '/opt/airflow/storage/user/2023-01-03'; 347)
[2023-01-02T16:42:41.702+0000] {local_task_job.py:164} INFO - Task exited with return code 1
[2023-01-02T16:42:42.393+0000] {local_task_job.py:273} INFO - 0 downstream tasks scheduled from follow-on schedule check
