[2023-01-07T04:55:18.152+0000] {taskinstance.py:1165} INFO - Dependencies all met for <TaskInstance: bq_process.conversion_stats.check_table manual__2023-01-07T04:55:08.833899+00:00 [queued]>
[2023-01-07T04:55:18.265+0000] {taskinstance.py:1165} INFO - Dependencies all met for <TaskInstance: bq_process.conversion_stats.check_table manual__2023-01-07T04:55:08.833899+00:00 [queued]>
[2023-01-07T04:55:18.267+0000] {taskinstance.py:1362} INFO - 
--------------------------------------------------------------------------------
[2023-01-07T04:55:18.269+0000] {taskinstance.py:1363} INFO - Starting attempt 1 of 1
[2023-01-07T04:55:18.271+0000] {taskinstance.py:1364} INFO - 
--------------------------------------------------------------------------------
[2023-01-07T04:55:18.526+0000] {taskinstance.py:1383} INFO - Executing <Task(BranchPythonOperator): conversion_stats.check_table> on 2023-01-07 04:55:08.833899+00:00
[2023-01-07T04:55:18.549+0000] {standard_task_runner.py:55} INFO - Started process 297 to run task
[2023-01-07T04:55:18.584+0000] {standard_task_runner.py:82} INFO - Running: ['***', 'tasks', 'run', 'bq_process', 'conversion_stats.check_table', 'manual__2023-01-07T04:55:08.833899+00:00', '--job-id', '528', '--raw', '--subdir', 'DAGS_FOLDER/bigquery_dag.py', '--cfg-path', '/tmp/tmpg7xrbop_']
[2023-01-07T04:55:18.619+0000] {standard_task_runner.py:83} INFO - Job 528: Subtask conversion_stats.check_table
[2023-01-07T04:55:19.208+0000] {task_command.py:376} INFO - Running <TaskInstance: bq_process.conversion_stats.check_table manual__2023-01-07T04:55:08.833899+00:00 [running]> on host fdf4acf1d8ed
[2023-01-07T04:55:19.704+0000] {taskinstance.py:1592} INFO - Exporting the following env vars:
AIRFLOW_CTX_DAG_OWNER=***
AIRFLOW_CTX_DAG_ID=bq_process
AIRFLOW_CTX_TASK_ID=conversion_stats.check_table
AIRFLOW_CTX_EXECUTION_DATE=2023-01-07T04:55:08.833899+00:00
AIRFLOW_CTX_TRY_NUMBER=1
AIRFLOW_CTX_DAG_RUN_ID=manual__2023-01-07T04:55:08.833899+00:00
[2023-01-07T04:55:20.427+0000] {python.py:177} INFO - Done. Returned value was: conversion_stats.insert_data
[2023-01-07T04:55:20.510+0000] {taskinstance.py:1851} ERROR - Task failed with exception
Traceback (most recent call last):
  File "/home/airflow/.local/lib/python3.7/site-packages/airflow/operators/python.py", line 225, in execute
    f"Branch callable must return valid task_ids. Invalid tasks found: {invalid_task_ids}"
airflow.exceptions.AirflowException: Branch callable must return valid task_ids. Invalid tasks found: {'conversion_stats.insert_data'}
[2023-01-07T04:55:20.531+0000] {taskinstance.py:1406} INFO - Marking task as FAILED. dag_id=bq_process, task_id=conversion_stats.check_table, execution_date=20230107T045508, start_date=20230107T045518, end_date=20230107T045520
[2023-01-07T04:55:20.607+0000] {standard_task_runner.py:105} ERROR - Failed to execute job 528 for task conversion_stats.check_table (Branch callable must return valid task_ids. Invalid tasks found: {'conversion_stats.insert_data'}; 297)
[2023-01-07T04:55:20.653+0000] {local_task_job.py:164} INFO - Task exited with return code 1
[2023-01-07T04:55:20.926+0000] {local_task_job.py:273} INFO - 0 downstream tasks scheduled from follow-on schedule check
