[2023-01-05T20:12:08.639+0000] {taskinstance.py:1165} INFO - Dependencies all met for <TaskInstance: dpt_cosmetic.create_dataset manual__2023-01-05T20:12:02.113730+00:00 [queued]>
[2023-01-05T20:12:08.707+0000] {taskinstance.py:1165} INFO - Dependencies all met for <TaskInstance: dpt_cosmetic.create_dataset manual__2023-01-05T20:12:02.113730+00:00 [queued]>
[2023-01-05T20:12:08.709+0000] {taskinstance.py:1362} INFO - 
--------------------------------------------------------------------------------
[2023-01-05T20:12:08.710+0000] {taskinstance.py:1363} INFO - Starting attempt 1 of 1
[2023-01-05T20:12:08.712+0000] {taskinstance.py:1364} INFO - 
--------------------------------------------------------------------------------
[2023-01-05T20:12:08.819+0000] {taskinstance.py:1383} INFO - Executing <Task(GCSToBigQueryOperator): create_dataset> on 2023-01-05 20:12:02.113730+00:00
[2023-01-05T20:12:08.838+0000] {standard_task_runner.py:55} INFO - Started process 65 to run task
[2023-01-05T20:12:08.862+0000] {standard_task_runner.py:82} INFO - Running: ['***', 'tasks', 'run', 'dpt_cosmetic', 'create_dataset', 'manual__2023-01-05T20:12:02.113730+00:00', '--job-id', '303', '--raw', '--subdir', 'DAGS_FOLDER/main.py', '--cfg-path', '/tmp/tmpz7tlpuil']
[2023-01-05T20:12:08.896+0000] {standard_task_runner.py:83} INFO - Job 303: Subtask create_dataset
[2023-01-05T20:12:09.351+0000] {task_command.py:376} INFO - Running <TaskInstance: dpt_cosmetic.create_dataset manual__2023-01-05T20:12:02.113730+00:00 [running]> on host fdf4acf1d8ed
[2023-01-05T20:12:09.921+0000] {taskinstance.py:1592} INFO - Exporting the following env vars:
AIRFLOW_CTX_DAG_OWNER=***
AIRFLOW_CTX_DAG_ID=dpt_cosmetic
AIRFLOW_CTX_TASK_ID=create_dataset
AIRFLOW_CTX_EXECUTION_DATE=2023-01-05T20:12:02.113730+00:00
AIRFLOW_CTX_TRY_NUMBER=1
AIRFLOW_CTX_DAG_RUN_ID=manual__2023-01-05T20:12:02.113730+00:00
[2023-01-05T20:12:09.926+0000] {connection.py:429} ERROR - Unable to retrieve connection from secrets backend (EnvironmentVariablesBackend). Checking subsequent secrets backend.
Traceback (most recent call last):
  File "/home/airflow/.local/lib/python3.7/site-packages/airflow/models/connection.py", line 422, in get_connection_from_secrets
    conn = secrets_backend.get_connection(conn_id=conn_id)
  File "/home/airflow/.local/lib/python3.7/site-packages/airflow/secrets/base_secrets.py", line 115, in get_connection
    return self.deserialize_connection(conn_id=conn_id, value=value)
  File "/home/airflow/.local/lib/python3.7/site-packages/airflow/secrets/base_secrets.py", line 67, in deserialize_connection
    return Connection.from_json(conn_id=conn_id, value=value)
  File "/home/airflow/.local/lib/python3.7/site-packages/airflow/models/connection.py", line 449, in from_json
    return Connection(conn_id=conn_id, **kwargs)
TypeError: __init__() got an unexpected keyword argument 'key_path'
[2023-01-05T20:12:09.983+0000] {base.py:71} INFO - Using connection ID 'google_cloud_default' for task execution.
[2023-01-05T20:12:10.020+0000] {bigquery.py:2842} INFO - Project not included in destination_project_dataset_table: cosmetic.user; using project "my-kubeflow-370515"
[2023-01-05T20:12:10.026+0000] {bigquery.py:1554} INFO - Inserting job ***_1672949530024070_20d2a02ff1029735793c6913161027ae
[2023-01-05T20:12:15.496+0000] {taskinstance.py:1406} INFO - Marking task as SUCCESS. dag_id=dpt_cosmetic, task_id=create_dataset, execution_date=20230105T201202, start_date=20230105T201208, end_date=20230105T201215
[2023-01-05T20:12:15.577+0000] {local_task_job.py:164} INFO - Task exited with return code 0
[2023-01-05T20:12:15.656+0000] {local_task_job.py:273} INFO - 0 downstream tasks scheduled from follow-on schedule check
