[2023-01-07T04:55:18.026+0000] {taskinstance.py:1165} INFO - Dependencies all met for <TaskInstance: bq_process.product_stats.check_table manual__2023-01-07T04:55:08.833899+00:00 [queued]>
[2023-01-07T04:55:18.212+0000] {taskinstance.py:1165} INFO - Dependencies all met for <TaskInstance: bq_process.product_stats.check_table manual__2023-01-07T04:55:08.833899+00:00 [queued]>
[2023-01-07T04:55:18.215+0000] {taskinstance.py:1362} INFO - 
--------------------------------------------------------------------------------
[2023-01-07T04:55:18.216+0000] {taskinstance.py:1363} INFO - Starting attempt 1 of 1
[2023-01-07T04:55:18.228+0000] {taskinstance.py:1364} INFO - 
--------------------------------------------------------------------------------
[2023-01-07T04:55:18.442+0000] {taskinstance.py:1383} INFO - Executing <Task(BranchPythonOperator): product_stats.check_table> on 2023-01-07 04:55:08.833899+00:00
[2023-01-07T04:55:18.481+0000] {standard_task_runner.py:55} INFO - Started process 296 to run task
[2023-01-07T04:55:18.500+0000] {standard_task_runner.py:82} INFO - Running: ['***', 'tasks', 'run', 'bq_process', 'product_stats.check_table', 'manual__2023-01-07T04:55:08.833899+00:00', '--job-id', '526', '--raw', '--subdir', 'DAGS_FOLDER/bigquery_dag.py', '--cfg-path', '/tmp/tmpryub39gs']
[2023-01-07T04:55:18.513+0000] {standard_task_runner.py:83} INFO - Job 526: Subtask product_stats.check_table
[2023-01-07T04:55:19.094+0000] {task_command.py:376} INFO - Running <TaskInstance: bq_process.product_stats.check_table manual__2023-01-07T04:55:08.833899+00:00 [running]> on host fdf4acf1d8ed
[2023-01-07T04:55:19.587+0000] {taskinstance.py:1592} INFO - Exporting the following env vars:
AIRFLOW_CTX_DAG_OWNER=***
AIRFLOW_CTX_DAG_ID=bq_process
AIRFLOW_CTX_TASK_ID=product_stats.check_table
AIRFLOW_CTX_EXECUTION_DATE=2023-01-07T04:55:08.833899+00:00
AIRFLOW_CTX_TRY_NUMBER=1
AIRFLOW_CTX_DAG_RUN_ID=manual__2023-01-07T04:55:08.833899+00:00
[2023-01-07T04:55:20.426+0000] {python.py:177} INFO - Done. Returned value was: product_stats.insert_data
[2023-01-07T04:55:20.534+0000] {taskinstance.py:1851} ERROR - Task failed with exception
Traceback (most recent call last):
  File "/home/airflow/.local/lib/python3.7/site-packages/airflow/operators/python.py", line 225, in execute
    f"Branch callable must return valid task_ids. Invalid tasks found: {invalid_task_ids}"
airflow.exceptions.AirflowException: Branch callable must return valid task_ids. Invalid tasks found: {'product_stats.insert_data'}
[2023-01-07T04:55:20.556+0000] {taskinstance.py:1406} INFO - Marking task as FAILED. dag_id=bq_process, task_id=product_stats.check_table, execution_date=20230107T045508, start_date=20230107T045518, end_date=20230107T045520
[2023-01-07T04:55:20.669+0000] {standard_task_runner.py:105} ERROR - Failed to execute job 526 for task product_stats.check_table (Branch callable must return valid task_ids. Invalid tasks found: {'product_stats.insert_data'}; 296)
[2023-01-07T04:55:20.745+0000] {local_task_job.py:164} INFO - Task exited with return code 1
[2023-01-07T04:55:21.090+0000] {local_task_job.py:273} INFO - 0 downstream tasks scheduled from follow-on schedule check
