[2023-01-02T15:42:05.925+0000] {taskinstance.py:1165} INFO - Dependencies all met for <TaskInstance: gcs.gcs_test manual__2023-01-02T15:42:02.521453+00:00 [queued]>
[2023-01-02T15:42:05.984+0000] {taskinstance.py:1165} INFO - Dependencies all met for <TaskInstance: gcs.gcs_test manual__2023-01-02T15:42:02.521453+00:00 [queued]>
[2023-01-02T15:42:05.985+0000] {taskinstance.py:1362} INFO - 
--------------------------------------------------------------------------------
[2023-01-02T15:42:05.987+0000] {taskinstance.py:1363} INFO - Starting attempt 1 of 1
[2023-01-02T15:42:05.988+0000] {taskinstance.py:1364} INFO - 
--------------------------------------------------------------------------------
[2023-01-02T15:42:06.059+0000] {taskinstance.py:1383} INFO - Executing <Task(PythonOperator): gcs_test> on 2023-01-02 15:42:02.521453+00:00
[2023-01-02T15:42:06.078+0000] {standard_task_runner.py:55} INFO - Started process 66 to run task
[2023-01-02T15:42:06.091+0000] {standard_task_runner.py:82} INFO - Running: ['***', 'tasks', 'run', 'gcs', 'gcs_test', 'manual__2023-01-02T15:42:02.521453+00:00', '--job-id', '206', '--raw', '--subdir', 'DAGS_FOLDER/gcs.py', '--cfg-path', '/tmp/tmp1aalf2ot']
[2023-01-02T15:42:06.098+0000] {standard_task_runner.py:83} INFO - Job 206: Subtask gcs_test
[2023-01-02T15:42:06.356+0000] {task_command.py:376} INFO - Running <TaskInstance: gcs.gcs_test manual__2023-01-02T15:42:02.521453+00:00 [running]> on host 703acec1b71e
[2023-01-02T15:42:06.674+0000] {taskinstance.py:1592} INFO - Exporting the following env vars:
AIRFLOW_CTX_DAG_OWNER=***
AIRFLOW_CTX_DAG_ID=gcs
AIRFLOW_CTX_TASK_ID=gcs_test
AIRFLOW_CTX_EXECUTION_DATE=2023-01-02T15:42:02.521453+00:00
AIRFLOW_CTX_TRY_NUMBER=1
AIRFLOW_CTX_DAG_RUN_ID=manual__2023-01-02T15:42:02.521453+00:00
[2023-01-02T15:42:06.678+0000] {connection.py:429} ERROR - Unable to retrieve connection from secrets backend (EnvironmentVariablesBackend). Checking subsequent secrets backend.
Traceback (most recent call last):
  File "/home/airflow/.local/lib/python3.7/site-packages/airflow/models/connection.py", line 422, in get_connection_from_secrets
    conn = secrets_backend.get_connection(conn_id=conn_id)
  File "/home/airflow/.local/lib/python3.7/site-packages/airflow/secrets/base_secrets.py", line 115, in get_connection
    return self.deserialize_connection(conn_id=conn_id, value=value)
  File "/home/airflow/.local/lib/python3.7/site-packages/airflow/secrets/base_secrets.py", line 67, in deserialize_connection
    return Connection.from_json(conn_id=conn_id, value=value)
  File "/home/airflow/.local/lib/python3.7/site-packages/airflow/models/connection.py", line 449, in from_json
    return Connection(conn_id=conn_id, **kwargs)
TypeError: __init__() got an unexpected keyword argument 'key_path'
[2023-01-02T15:42:06.715+0000] {base.py:71} INFO - Using connection ID 'google_cloud_default' for task execution.
[2023-01-02T15:42:06.764+0000] {taskinstance.py:1851} ERROR - Task failed with exception
Traceback (most recent call last):
  File "/home/airflow/.local/lib/python3.7/site-packages/airflow/operators/python.py", line 175, in execute
    return_value = self.execute_callable()
  File "/home/airflow/.local/lib/python3.7/site-packages/airflow/operators/python.py", line 193, in execute_callable
    return self.python_callable(*self.op_args, **self.op_kwargs)
  File "/opt/airflow/dags/gcs.py", line 18, in upload_to_gcs
    gcs.upload(bucket,dest,local)
  File "/home/airflow/.local/lib/python3.7/site-packages/airflow/providers/google/cloud/hooks/gcs.py", line 513, in upload
    partial(blob.upload_from_filename, filename=filename, content_type=mime_type, timeout=timeout)
  File "/home/airflow/.local/lib/python3.7/site-packages/airflow/providers/google/cloud/hooks/gcs.py", line 470, in _call_with_retry
    f()
  File "/home/airflow/.local/lib/python3.7/site-packages/google/cloud/storage/blob.py", line 2720, in upload_from_filename
    with open(filename, "rb") as file_obj:
FileNotFoundError: [Errno 2] No such file or directory: '/opt/airflow/user/main.txt'
[2023-01-02T15:42:06.811+0000] {taskinstance.py:1406} INFO - Marking task as FAILED. dag_id=gcs, task_id=gcs_test, execution_date=20230102T154202, start_date=20230102T154205, end_date=20230102T154206
[2023-01-02T15:42:06.854+0000] {standard_task_runner.py:105} ERROR - Failed to execute job 206 for task gcs_test ([Errno 2] No such file or directory: '/opt/airflow/user/main.txt'; 66)
[2023-01-02T15:42:06.905+0000] {local_task_job.py:164} INFO - Task exited with return code 1
[2023-01-02T15:42:07.005+0000] {local_task_job.py:273} INFO - 0 downstream tasks scheduled from follow-on schedule check
