[2023-01-06T01:53:09.932+0000] {taskinstance.py:1165} INFO - Dependencies all met for <TaskInstance: dpt_cosmetic.user_01.check_table manual__2023-01-06T01:53:06.925404+00:00 [queued]>
[2023-01-06T01:53:09.945+0000] {taskinstance.py:1165} INFO - Dependencies all met for <TaskInstance: dpt_cosmetic.user_01.check_table manual__2023-01-06T01:53:06.925404+00:00 [queued]>
[2023-01-06T01:53:09.946+0000] {taskinstance.py:1362} INFO - 
--------------------------------------------------------------------------------
[2023-01-06T01:53:09.947+0000] {taskinstance.py:1363} INFO - Starting attempt 1 of 1
[2023-01-06T01:53:09.947+0000] {taskinstance.py:1364} INFO - 
--------------------------------------------------------------------------------
[2023-01-06T01:53:09.970+0000] {taskinstance.py:1383} INFO - Executing <Task(BranchPythonOperator): user_01.check_table> on 2023-01-06 01:53:06.925404+00:00
[2023-01-06T01:53:09.977+0000] {standard_task_runner.py:55} INFO - Started process 105 to run task
[2023-01-06T01:53:09.982+0000] {standard_task_runner.py:82} INFO - Running: ['***', 'tasks', 'run', 'dpt_cosmetic', 'user_01.check_table', 'manual__2023-01-06T01:53:06.925404+00:00', '--job-id', '348', '--raw', '--subdir', 'DAGS_FOLDER/main.py', '--cfg-path', '/tmp/tmpxegea69f']
[2023-01-06T01:53:09.985+0000] {standard_task_runner.py:83} INFO - Job 348: Subtask user_01.check_table
[2023-01-06T01:53:10.143+0000] {task_command.py:376} INFO - Running <TaskInstance: dpt_cosmetic.user_01.check_table manual__2023-01-06T01:53:06.925404+00:00 [running]> on host fdf4acf1d8ed
[2023-01-06T01:53:10.263+0000] {taskinstance.py:1592} INFO - Exporting the following env vars:
AIRFLOW_CTX_DAG_OWNER=***
AIRFLOW_CTX_DAG_ID=dpt_cosmetic
AIRFLOW_CTX_TASK_ID=user_01.check_table
AIRFLOW_CTX_EXECUTION_DATE=2023-01-06T01:53:06.925404+00:00
AIRFLOW_CTX_TRY_NUMBER=1
AIRFLOW_CTX_DAG_RUN_ID=manual__2023-01-06T01:53:06.925404+00:00
[2023-01-06T01:53:10.953+0000] {python.py:177} INFO - Done. Returned value was: user_01_insert_data
[2023-01-06T01:53:10.972+0000] {taskinstance.py:1851} ERROR - Task failed with exception
Traceback (most recent call last):
  File "/home/airflow/.local/lib/python3.7/site-packages/airflow/operators/python.py", line 225, in execute
    f"Branch callable must return valid task_ids. Invalid tasks found: {invalid_task_ids}"
airflow.exceptions.AirflowException: Branch callable must return valid task_ids. Invalid tasks found: {'user_01_insert_data'}
[2023-01-06T01:53:10.980+0000] {taskinstance.py:1406} INFO - Marking task as FAILED. dag_id=dpt_cosmetic, task_id=user_01.check_table, execution_date=20230106T015306, start_date=20230106T015309, end_date=20230106T015310
[2023-01-06T01:53:11.011+0000] {standard_task_runner.py:105} ERROR - Failed to execute job 348 for task user_01.check_table (Branch callable must return valid task_ids. Invalid tasks found: {'user_01_insert_data'}; 105)
[2023-01-06T01:53:11.040+0000] {local_task_job.py:164} INFO - Task exited with return code 1
[2023-01-06T01:53:11.098+0000] {local_task_job.py:273} INFO - 0 downstream tasks scheduled from follow-on schedule check
