[2023-01-01T00:00:17.251+0000] {taskinstance.py:1165} INFO - Dependencies all met for <TaskInstance: dpt_cosmetic.user.extract manual__2023-01-01T00:00:00.648197+00:00 [queued]>
[2023-01-01T00:00:17.315+0000] {taskinstance.py:1165} INFO - Dependencies all met for <TaskInstance: dpt_cosmetic.user.extract manual__2023-01-01T00:00:00.648197+00:00 [queued]>
[2023-01-01T00:00:17.317+0000] {taskinstance.py:1362} INFO - 
--------------------------------------------------------------------------------
[2023-01-01T00:00:17.319+0000] {taskinstance.py:1363} INFO - Starting attempt 1 of 1
[2023-01-01T00:00:17.321+0000] {taskinstance.py:1364} INFO - 
--------------------------------------------------------------------------------
[2023-01-01T00:00:17.417+0000] {taskinstance.py:1383} INFO - Executing <Task(ExtractOperator): user.extract> on 2023-01-01 00:00:00.648197+00:00
[2023-01-01T00:00:17.433+0000] {standard_task_runner.py:55} INFO - Started process 517 to run task
[2023-01-01T00:00:17.459+0000] {standard_task_runner.py:82} INFO - Running: ['***', 'tasks', 'run', 'dpt_cosmetic', 'user.extract', 'manual__2023-01-01T00:00:00.648197+00:00', '--job-id', '85', '--raw', '--subdir', 'DAGS_FOLDER/main.py', '--cfg-path', '/tmp/tmp3etl5p5k']
[2023-01-01T00:00:17.462+0000] {standard_task_runner.py:83} INFO - Job 85: Subtask user.extract
[2023-01-01T00:00:17.826+0000] {task_command.py:376} INFO - Running <TaskInstance: dpt_cosmetic.user.extract manual__2023-01-01T00:00:00.648197+00:00 [running]> on host 6bd76effbc07
[2023-01-01T00:00:18.212+0000] {taskinstance.py:1592} INFO - Exporting the following env vars:
AIRFLOW_CTX_DAG_OWNER=***
AIRFLOW_CTX_DAG_ID=dpt_cosmetic
AIRFLOW_CTX_TASK_ID=user.extract
AIRFLOW_CTX_EXECUTION_DATE=2023-01-01T00:00:00.648197+00:00
AIRFLOW_CTX_TRY_NUMBER=1
AIRFLOW_CTX_DAG_RUN_ID=manual__2023-01-01T00:00:00.648197+00:00
[2023-01-01T00:00:18.215+0000] {taskinstance.py:1851} ERROR - Task failed with exception
Traceback (most recent call last):
  File "/opt/airflow/dags/utilties/extract_operator.py", line 15, in execute
    {"first_created":{"$gte":self.filter['start'],"$lt":self.filter['end']}}
TypeError: must be str, not dict
[2023-01-01T00:00:18.285+0000] {taskinstance.py:1406} INFO - Marking task as FAILED. dag_id=dpt_cosmetic, task_id=user.extract, execution_date=20230101T000000, start_date=20230101T000017, end_date=20230101T000018
[2023-01-01T00:00:18.357+0000] {standard_task_runner.py:105} ERROR - Failed to execute job 85 for task user.extract (must be str, not dict; 517)
[2023-01-01T00:00:18.402+0000] {local_task_job.py:164} INFO - Task exited with return code 1
[2023-01-01T00:00:18.543+0000] {local_task_job.py:273} INFO - 0 downstream tasks scheduled from follow-on schedule check
