[2023-01-02T15:08:00.915+0000] {taskinstance.py:1165} INFO - Dependencies all met for <TaskInstance: gcs.gcs_test manual__2023-01-02T15:07:56.736360+00:00 [queued]>
[2023-01-02T15:08:00.984+0000] {taskinstance.py:1165} INFO - Dependencies all met for <TaskInstance: gcs.gcs_test manual__2023-01-02T15:07:56.736360+00:00 [queued]>
[2023-01-02T15:08:00.985+0000] {taskinstance.py:1362} INFO - 
--------------------------------------------------------------------------------
[2023-01-02T15:08:00.987+0000] {taskinstance.py:1363} INFO - Starting attempt 1 of 1
[2023-01-02T15:08:00.988+0000] {taskinstance.py:1364} INFO - 
--------------------------------------------------------------------------------
[2023-01-02T15:08:01.080+0000] {taskinstance.py:1383} INFO - Executing <Task(PythonOperator): gcs_test> on 2023-01-02 15:07:56.736360+00:00
[2023-01-02T15:08:01.103+0000] {standard_task_runner.py:55} INFO - Started process 61 to run task
[2023-01-02T15:08:01.121+0000] {standard_task_runner.py:82} INFO - Running: ['***', 'tasks', 'run', 'gcs', 'gcs_test', 'manual__2023-01-02T15:07:56.736360+00:00', '--job-id', '198', '--raw', '--subdir', 'DAGS_FOLDER/gcs.py', '--cfg-path', '/tmp/tmpajwc_1dt']
[2023-01-02T15:08:01.132+0000] {standard_task_runner.py:83} INFO - Job 198: Subtask gcs_test
[2023-01-02T15:08:01.436+0000] {task_command.py:376} INFO - Running <TaskInstance: gcs.gcs_test manual__2023-01-02T15:07:56.736360+00:00 [running]> on host 703acec1b71e
[2023-01-02T15:08:01.771+0000] {taskinstance.py:1592} INFO - Exporting the following env vars:
AIRFLOW_CTX_DAG_OWNER=***
AIRFLOW_CTX_DAG_ID=gcs
AIRFLOW_CTX_TASK_ID=gcs_test
AIRFLOW_CTX_EXECUTION_DATE=2023-01-02T15:07:56.736360+00:00
AIRFLOW_CTX_TRY_NUMBER=1
AIRFLOW_CTX_DAG_RUN_ID=manual__2023-01-02T15:07:56.736360+00:00
[2023-01-02T15:08:01.775+0000] {connection.py:429} ERROR - Unable to retrieve connection from secrets backend (EnvironmentVariablesBackend). Checking subsequent secrets backend.
Traceback (most recent call last):
  File "/home/airflow/.local/lib/python3.7/site-packages/airflow/models/connection.py", line 422, in get_connection_from_secrets
    conn = secrets_backend.get_connection(conn_id=conn_id)
  File "/home/airflow/.local/lib/python3.7/site-packages/airflow/secrets/base_secrets.py", line 115, in get_connection
    return self.deserialize_connection(conn_id=conn_id, value=value)
  File "/home/airflow/.local/lib/python3.7/site-packages/airflow/secrets/base_secrets.py", line 67, in deserialize_connection
    return Connection.from_json(conn_id=conn_id, value=value)
  File "/home/airflow/.local/lib/python3.7/site-packages/airflow/models/connection.py", line 449, in from_json
    return Connection(conn_id=conn_id, **kwargs)
TypeError: __init__() got an unexpected keyword argument 'key_path'
[2023-01-02T15:08:01.852+0000] {taskinstance.py:1851} ERROR - Task failed with exception
Traceback (most recent call last):
  File "/home/airflow/.local/lib/python3.7/site-packages/airflow/operators/python.py", line 175, in execute
    return_value = self.execute_callable()
  File "/home/airflow/.local/lib/python3.7/site-packages/airflow/operators/python.py", line 193, in execute_callable
    return self.python_callable(*self.op_args, **self.op_kwargs)
  File "/opt/airflow/dags/gcs.py", line 12, in upload_to_gcs
    gcs=GoogleCloudStorageHook()
  File "/home/airflow/.local/lib/python3.7/site-packages/airflow/providers/google/cloud/hooks/gcs.py", line 145, in __init__
    impersonation_chain=impersonation_chain,
  File "/home/airflow/.local/lib/python3.7/site-packages/airflow/providers/google/common/hooks/base_google.py", line 226, in __init__
    self.extras = self.get_connection(self.gcp_conn_id).extra_dejson  # type: Dict
  File "/home/airflow/.local/lib/python3.7/site-packages/airflow/hooks/base.py", line 70, in get_connection
    conn = Connection.get_connection_from_secrets(conn_id)
  File "/home/airflow/.local/lib/python3.7/site-packages/airflow/models/connection.py", line 432, in get_connection_from_secrets
    raise AirflowNotFoundException(f"The conn_id `{conn_id}` isn't defined")
airflow.exceptions.AirflowNotFoundException: The conn_id `google_cloud_default` isn't defined
[2023-01-02T15:08:01.883+0000] {taskinstance.py:1406} INFO - Marking task as FAILED. dag_id=gcs, task_id=gcs_test, execution_date=20230102T150756, start_date=20230102T150800, end_date=20230102T150801
[2023-01-02T15:08:01.936+0000] {standard_task_runner.py:105} ERROR - Failed to execute job 198 for task gcs_test (The conn_id `google_cloud_default` isn't defined; 61)
[2023-01-02T15:08:01.974+0000] {local_task_job.py:164} INFO - Task exited with return code 1
[2023-01-02T15:08:02.065+0000] {local_task_job.py:273} INFO - 0 downstream tasks scheduled from follow-on schedule check
