[2023-01-01T13:47:10.961+0000] {taskinstance.py:1165} INFO - Dependencies all met for <TaskInstance: dpt_cosmetic.transaction.transform manual__2023-01-01T13:46:59.292514+00:00 [queued]>
[2023-01-01T13:47:11.017+0000] {taskinstance.py:1165} INFO - Dependencies all met for <TaskInstance: dpt_cosmetic.transaction.transform manual__2023-01-01T13:46:59.292514+00:00 [queued]>
[2023-01-01T13:47:11.019+0000] {taskinstance.py:1362} INFO - 
--------------------------------------------------------------------------------
[2023-01-01T13:47:11.020+0000] {taskinstance.py:1363} INFO - Starting attempt 1 of 1
[2023-01-01T13:47:11.022+0000] {taskinstance.py:1364} INFO - 
--------------------------------------------------------------------------------
[2023-01-01T13:47:11.103+0000] {taskinstance.py:1383} INFO - Executing <Task(Operator): transaction.transform> on 2023-01-01 13:46:59.292514+00:00
[2023-01-01T13:47:11.119+0000] {standard_task_runner.py:55} INFO - Started process 272 to run task
[2023-01-01T13:47:11.137+0000] {standard_task_runner.py:82} INFO - Running: ['***', 'tasks', 'run', 'dpt_cosmetic', 'transaction.transform', 'manual__2023-01-01T13:46:59.292514+00:00', '--job-id', '186', '--raw', '--subdir', 'DAGS_FOLDER/main.py', '--cfg-path', '/tmp/tmpkbiem68a']
[2023-01-01T13:47:11.141+0000] {standard_task_runner.py:83} INFO - Job 186: Subtask transaction.transform
[2023-01-01T13:47:11.451+0000] {task_command.py:376} INFO - Running <TaskInstance: dpt_cosmetic.transaction.transform manual__2023-01-01T13:46:59.292514+00:00 [running]> on host 6bd76effbc07
[2023-01-01T13:47:11.805+0000] {taskinstance.py:1592} INFO - Exporting the following env vars:
AIRFLOW_CTX_DAG_OWNER=***
AIRFLOW_CTX_DAG_ID=dpt_cosmetic
AIRFLOW_CTX_TASK_ID=transaction.transform
AIRFLOW_CTX_EXECUTION_DATE=2023-01-01T13:46:59.292514+00:00
AIRFLOW_CTX_TRY_NUMBER=1
AIRFLOW_CTX_DAG_RUN_ID=manual__2023-01-01T13:46:59.292514+00:00
[2023-01-01T13:47:19.933+0000] {taskinstance.py:1851} ERROR - Task failed with exception
Traceback (most recent call last):
  File "/opt/airflow/dags/utilties/operator.py", line 90, in execute
    df=self.transform_trans(df)
  File "/opt/airflow/dags/utilties/operator.py", line 37, in transform_trans
    trans=trans[~(trans.user_agent.map(lambda x:crawler_check(x)))]
  File "/home/airflow/.local/lib/python3.7/site-packages/pandas/core/generic.py", line 5487, in __getattr__
    return object.__getattribute__(self, name)
AttributeError: 'DataFrame' object has no attribute 'user_agent'
[2023-01-01T13:47:19.980+0000] {taskinstance.py:1406} INFO - Marking task as FAILED. dag_id=dpt_cosmetic, task_id=transaction.transform, execution_date=20230101T134659, start_date=20230101T134710, end_date=20230101T134719
[2023-01-01T13:47:20.043+0000] {standard_task_runner.py:105} ERROR - Failed to execute job 186 for task transaction.transform ('DataFrame' object has no attribute 'user_agent'; 272)
[2023-01-01T13:47:20.117+0000] {local_task_job.py:164} INFO - Task exited with return code 1
[2023-01-01T13:47:20.208+0000] {local_task_job.py:273} INFO - 0 downstream tasks scheduled from follow-on schedule check
