[2023-01-01T13:14:53.827+0000] {taskinstance.py:1165} INFO - Dependencies all met for <TaskInstance: dpt_cosmetic.user.transform manual__2023-01-01T13:14:40.125399+00:00 [queued]>
[2023-01-01T13:14:53.887+0000] {taskinstance.py:1165} INFO - Dependencies all met for <TaskInstance: dpt_cosmetic.user.transform manual__2023-01-01T13:14:40.125399+00:00 [queued]>
[2023-01-01T13:14:53.888+0000] {taskinstance.py:1362} INFO - 
--------------------------------------------------------------------------------
[2023-01-01T13:14:53.890+0000] {taskinstance.py:1363} INFO - Starting attempt 1 of 1
[2023-01-01T13:14:53.892+0000] {taskinstance.py:1364} INFO - 
--------------------------------------------------------------------------------
[2023-01-01T13:14:53.998+0000] {taskinstance.py:1383} INFO - Executing <Task(Operator): user.transform> on 2023-01-01 13:14:40.125399+00:00
[2023-01-01T13:14:54.022+0000] {standard_task_runner.py:55} INFO - Started process 98 to run task
[2023-01-01T13:14:54.036+0000] {standard_task_runner.py:82} INFO - Running: ['***', 'tasks', 'run', 'dpt_cosmetic', 'user.transform', 'manual__2023-01-01T13:14:40.125399+00:00', '--job-id', '166', '--raw', '--subdir', 'DAGS_FOLDER/main.py', '--cfg-path', '/tmp/tmpcm_q96jq']
[2023-01-01T13:14:54.039+0000] {standard_task_runner.py:83} INFO - Job 166: Subtask user.transform
[2023-01-01T13:14:54.329+0000] {task_command.py:376} INFO - Running <TaskInstance: dpt_cosmetic.user.transform manual__2023-01-01T13:14:40.125399+00:00 [running]> on host 6bd76effbc07
[2023-01-01T13:14:54.651+0000] {taskinstance.py:1592} INFO - Exporting the following env vars:
AIRFLOW_CTX_DAG_OWNER=***
AIRFLOW_CTX_DAG_ID=dpt_cosmetic
AIRFLOW_CTX_TASK_ID=user.transform
AIRFLOW_CTX_EXECUTION_DATE=2023-01-01T13:14:40.125399+00:00
AIRFLOW_CTX_TRY_NUMBER=1
AIRFLOW_CTX_DAG_RUN_ID=manual__2023-01-01T13:14:40.125399+00:00
[2023-01-01T13:14:54.832+0000] {taskinstance.py:1851} ERROR - Task failed with exception
Traceback (most recent call last):
  File "/opt/airflow/dags/utilties/operator.py", line 85, in execute
    df=self.transform_user(df)
  File "/opt/airflow/dags/utilties/operator.py", line 22, in transform_user
    user['gender']=user.gender.map(lambda x:"F" if x[0].lower()=='f' else "M")
  File "/home/airflow/.local/lib/python3.7/site-packages/pandas/core/generic.py", line 5487, in __getattr__
    return object.__getattribute__(self, name)
AttributeError: 'DataFrame' object has no attribute 'gender'
[2023-01-01T13:14:54.881+0000] {taskinstance.py:1406} INFO - Marking task as FAILED. dag_id=dpt_cosmetic, task_id=user.transform, execution_date=20230101T131440, start_date=20230101T131453, end_date=20230101T131454
[2023-01-01T13:14:54.942+0000] {standard_task_runner.py:105} ERROR - Failed to execute job 166 for task user.transform ('DataFrame' object has no attribute 'gender'; 98)
[2023-01-01T13:14:54.971+0000] {local_task_job.py:164} INFO - Task exited with return code 1
[2023-01-01T13:14:55.070+0000] {local_task_job.py:273} INFO - 0 downstream tasks scheduled from follow-on schedule check
