[2023-01-02T16:32:26.623+0000] {taskinstance.py:1165} INFO - Dependencies all met for <TaskInstance: dpt_cosmetic.transaction.load_to_google_storage scheduled__2023-01-01T00:00:00+00:00 [queued]>
[2023-01-02T16:32:26.830+0000] {taskinstance.py:1165} INFO - Dependencies all met for <TaskInstance: dpt_cosmetic.transaction.load_to_google_storage scheduled__2023-01-01T00:00:00+00:00 [queued]>
[2023-01-02T16:32:26.889+0000] {taskinstance.py:1362} INFO - 
--------------------------------------------------------------------------------
[2023-01-02T16:32:26.892+0000] {taskinstance.py:1363} INFO - Starting attempt 1 of 1
[2023-01-02T16:32:26.894+0000] {taskinstance.py:1364} INFO - 
--------------------------------------------------------------------------------
[2023-01-02T16:32:27.201+0000] {taskinstance.py:1383} INFO - Executing <Task(LocalToStorageOperator): transaction.load_to_google_storage> on 2023-01-01 00:00:00+00:00
[2023-01-02T16:32:27.274+0000] {standard_task_runner.py:82} INFO - Running: ['***', 'tasks', 'run', 'dpt_cosmetic', 'transaction.load_to_google_storage', 'scheduled__2023-01-01T00:00:00+00:00', '--job-id', '223', '--raw', '--subdir', 'DAGS_FOLDER/main.py', '--cfg-path', '/tmp/tmpj1qs7gee']
[2023-01-02T16:32:27.280+0000] {standard_task_runner.py:83} INFO - Job 223: Subtask transaction.load_to_google_storage
[2023-01-02T16:32:27.280+0000] {standard_task_runner.py:55} INFO - Started process 213 to run task
[2023-01-02T16:32:27.376+0000] {warnings.py:110} WARNING - /home/***/.local/lib/python3.7/site-packages/***/configuration.py:545: DeprecationWarning: The sql_alchemy_conn option in [core] has been moved to the sql_alchemy_conn option in [database] - the old setting has been used, but please update your config.
  option = self._get_environment_variables(deprecated_key, deprecated_section, key, section)

[2023-01-02T16:32:28.739+0000] {task_command.py:376} INFO - Running <TaskInstance: dpt_cosmetic.transaction.load_to_google_storage scheduled__2023-01-01T00:00:00+00:00 [running]> on host 703acec1b71e
[2023-01-02T16:32:29.571+0000] {taskinstance.py:1592} INFO - Exporting the following env vars:
AIRFLOW_CTX_DAG_OWNER=***
AIRFLOW_CTX_DAG_ID=dpt_cosmetic
AIRFLOW_CTX_TASK_ID=transaction.load_to_google_storage
AIRFLOW_CTX_EXECUTION_DATE=2023-01-01T00:00:00+00:00
AIRFLOW_CTX_TRY_NUMBER=1
AIRFLOW_CTX_DAG_RUN_ID=scheduled__2023-01-01T00:00:00+00:00
[2023-01-02T16:32:29.598+0000] {connection.py:429} ERROR - Unable to retrieve connection from secrets backend (EnvironmentVariablesBackend). Checking subsequent secrets backend.
Traceback (most recent call last):
  File "/home/airflow/.local/lib/python3.7/site-packages/airflow/models/connection.py", line 422, in get_connection_from_secrets
    conn = secrets_backend.get_connection(conn_id=conn_id)
  File "/home/airflow/.local/lib/python3.7/site-packages/airflow/secrets/base_secrets.py", line 115, in get_connection
    return self.deserialize_connection(conn_id=conn_id, value=value)
  File "/home/airflow/.local/lib/python3.7/site-packages/airflow/secrets/base_secrets.py", line 67, in deserialize_connection
    return Connection.from_json(conn_id=conn_id, value=value)
  File "/home/airflow/.local/lib/python3.7/site-packages/airflow/models/connection.py", line 449, in from_json
    return Connection(conn_id=conn_id, **kwargs)
TypeError: __init__() got an unexpected keyword argument 'key_path'
[2023-01-02T16:32:29.737+0000] {base.py:71} INFO - Using connection ID 'google_cloud_default' for task execution.
[2023-01-02T16:32:29.836+0000] {taskinstance.py:1851} ERROR - Task failed with exception
Traceback (most recent call last):
  File "/opt/airflow/dags/utilties/operator.py", line 27, in execute
    gcs.upload(self.bucket,self.dest_path,self.local_path)
  File "/home/airflow/.local/lib/python3.7/site-packages/airflow/providers/google/cloud/hooks/gcs.py", line 489, in upload
    bucket = client.bucket(bucket_name)
  File "/home/airflow/.local/lib/python3.7/site-packages/google/cloud/storage/client.py", line 279, in bucket
    return Bucket(client=self, name=bucket_name, user_project=user_project)
  File "/home/airflow/.local/lib/python3.7/site-packages/google/cloud/storage/bucket.py", line 611, in __init__
    name = _validate_name(name)
  File "/home/airflow/.local/lib/python3.7/site-packages/google/cloud/storage/_helpers.py", line 81, in _validate_name
    raise ValueError("Bucket names must start and end with a number or letter.")
ValueError: Bucket names must start and end with a number or letter.
[2023-01-02T16:32:29.949+0000] {taskinstance.py:1406} INFO - Marking task as FAILED. dag_id=dpt_cosmetic, task_id=transaction.load_to_google_storage, execution_date=20230101T000000, start_date=20230102T163226, end_date=20230102T163229
[2023-01-02T16:32:30.071+0000] {standard_task_runner.py:105} ERROR - Failed to execute job 223 for task transaction.load_to_google_storage (Bucket names must start and end with a number or letter.; 213)
[2023-01-02T16:32:30.182+0000] {local_task_job.py:164} INFO - Task exited with return code 1
[2023-01-02T16:32:30.527+0000] {local_task_job.py:273} INFO - 0 downstream tasks scheduled from follow-on schedule check
[2023-01-02T16:38:04.761+0000] {taskinstance.py:1165} INFO - Dependencies all met for <TaskInstance: dpt_cosmetic.transaction.load_to_google_storage scheduled__2023-01-01T00:00:00+00:00 [queued]>
[2023-01-02T16:38:04.810+0000] {taskinstance.py:1165} INFO - Dependencies all met for <TaskInstance: dpt_cosmetic.transaction.load_to_google_storage scheduled__2023-01-01T00:00:00+00:00 [queued]>
[2023-01-02T16:38:04.812+0000] {taskinstance.py:1362} INFO - 
--------------------------------------------------------------------------------
[2023-01-02T16:38:04.814+0000] {taskinstance.py:1363} INFO - Starting attempt 1 of 1
[2023-01-02T16:38:04.816+0000] {taskinstance.py:1364} INFO - 
--------------------------------------------------------------------------------
[2023-01-02T16:38:04.889+0000] {taskinstance.py:1383} INFO - Executing <Task(LocalToStorageOperator): transaction.load_to_google_storage> on 2023-01-01 00:00:00+00:00
[2023-01-02T16:38:04.908+0000] {standard_task_runner.py:55} INFO - Started process 316 to run task
[2023-01-02T16:38:04.923+0000] {standard_task_runner.py:82} INFO - Running: ['***', 'tasks', 'run', 'dpt_cosmetic', 'transaction.load_to_google_storage', 'scheduled__2023-01-01T00:00:00+00:00', '--job-id', '239', '--raw', '--subdir', 'DAGS_FOLDER/main.py', '--cfg-path', '/tmp/tmpu8k8vpqh']
[2023-01-02T16:38:04.926+0000] {standard_task_runner.py:83} INFO - Job 239: Subtask transaction.load_to_google_storage
[2023-01-02T16:38:04.982+0000] {warnings.py:110} WARNING - /home/***/.local/lib/python3.7/site-packages/***/configuration.py:545: DeprecationWarning: The sql_alchemy_conn option in [core] has been moved to the sql_alchemy_conn option in [database] - the old setting has been used, but please update your config.
  option = self._get_environment_variables(deprecated_key, deprecated_section, key, section)

[2023-01-02T16:38:05.942+0000] {task_command.py:376} INFO - Running <TaskInstance: dpt_cosmetic.transaction.load_to_google_storage scheduled__2023-01-01T00:00:00+00:00 [running]> on host 703acec1b71e
[2023-01-02T16:38:06.315+0000] {taskinstance.py:1592} INFO - Exporting the following env vars:
AIRFLOW_CTX_DAG_OWNER=***
AIRFLOW_CTX_DAG_ID=dpt_cosmetic
AIRFLOW_CTX_TASK_ID=transaction.load_to_google_storage
AIRFLOW_CTX_EXECUTION_DATE=2023-01-01T00:00:00+00:00
AIRFLOW_CTX_TRY_NUMBER=1
AIRFLOW_CTX_DAG_RUN_ID=scheduled__2023-01-01T00:00:00+00:00
[2023-01-02T16:38:06.319+0000] {connection.py:429} ERROR - Unable to retrieve connection from secrets backend (EnvironmentVariablesBackend). Checking subsequent secrets backend.
Traceback (most recent call last):
  File "/home/airflow/.local/lib/python3.7/site-packages/airflow/models/connection.py", line 422, in get_connection_from_secrets
    conn = secrets_backend.get_connection(conn_id=conn_id)
  File "/home/airflow/.local/lib/python3.7/site-packages/airflow/secrets/base_secrets.py", line 115, in get_connection
    return self.deserialize_connection(conn_id=conn_id, value=value)
  File "/home/airflow/.local/lib/python3.7/site-packages/airflow/secrets/base_secrets.py", line 67, in deserialize_connection
    return Connection.from_json(conn_id=conn_id, value=value)
  File "/home/airflow/.local/lib/python3.7/site-packages/airflow/models/connection.py", line 449, in from_json
    return Connection(conn_id=conn_id, **kwargs)
TypeError: __init__() got an unexpected keyword argument 'key_path'
[2023-01-02T16:38:06.351+0000] {base.py:71} INFO - Using connection ID 'google_cloud_default' for task execution.
[2023-01-02T16:38:06.384+0000] {taskinstance.py:1851} ERROR - Task failed with exception
Traceback (most recent call last):
  File "/opt/airflow/dags/utilties/operator.py", line 27, in execute
    gcs.upload(self.bucket,self.dest_path,self.local_path)
  File "/home/airflow/.local/lib/python3.7/site-packages/airflow/providers/google/cloud/hooks/gcs.py", line 489, in upload
    bucket = client.bucket(bucket_name)
  File "/home/airflow/.local/lib/python3.7/site-packages/google/cloud/storage/client.py", line 279, in bucket
    return Bucket(client=self, name=bucket_name, user_project=user_project)
  File "/home/airflow/.local/lib/python3.7/site-packages/google/cloud/storage/bucket.py", line 611, in __init__
    name = _validate_name(name)
  File "/home/airflow/.local/lib/python3.7/site-packages/google/cloud/storage/_helpers.py", line 81, in _validate_name
    raise ValueError("Bucket names must start and end with a number or letter.")
ValueError: Bucket names must start and end with a number or letter.
[2023-01-02T16:38:06.441+0000] {taskinstance.py:1406} INFO - Marking task as FAILED. dag_id=dpt_cosmetic, task_id=transaction.load_to_google_storage, execution_date=20230101T000000, start_date=20230102T163804, end_date=20230102T163806
[2023-01-02T16:38:06.502+0000] {standard_task_runner.py:105} ERROR - Failed to execute job 239 for task transaction.load_to_google_storage (Bucket names must start and end with a number or letter.; 316)
[2023-01-02T16:38:06.585+0000] {local_task_job.py:164} INFO - Task exited with return code 1
[2023-01-02T16:38:07.260+0000] {local_task_job.py:273} INFO - 0 downstream tasks scheduled from follow-on schedule check
[2023-01-02T16:45:28.900+0000] {taskinstance.py:1165} INFO - Dependencies all met for <TaskInstance: dpt_cosmetic.transaction.load_to_google_storage scheduled__2023-01-01T00:00:00+00:00 [queued]>
[2023-01-02T16:45:28.951+0000] {taskinstance.py:1165} INFO - Dependencies all met for <TaskInstance: dpt_cosmetic.transaction.load_to_google_storage scheduled__2023-01-01T00:00:00+00:00 [queued]>
[2023-01-02T16:45:28.953+0000] {taskinstance.py:1362} INFO - 
--------------------------------------------------------------------------------
[2023-01-02T16:45:28.954+0000] {taskinstance.py:1363} INFO - Starting attempt 1 of 1
[2023-01-02T16:45:28.956+0000] {taskinstance.py:1364} INFO - 
--------------------------------------------------------------------------------
[2023-01-02T16:45:29.036+0000] {taskinstance.py:1383} INFO - Executing <Task(LocalToStorageOperator): transaction.load_to_google_storage> on 2023-01-01 00:00:00+00:00
[2023-01-02T16:45:29.053+0000] {standard_task_runner.py:55} INFO - Started process 427 to run task
[2023-01-02T16:45:29.068+0000] {standard_task_runner.py:82} INFO - Running: ['***', 'tasks', 'run', 'dpt_cosmetic', 'transaction.load_to_google_storage', 'scheduled__2023-01-01T00:00:00+00:00', '--job-id', '254', '--raw', '--subdir', 'DAGS_FOLDER/main.py', '--cfg-path', '/tmp/tmp67uh1gmg']
[2023-01-02T16:45:29.070+0000] {standard_task_runner.py:83} INFO - Job 254: Subtask transaction.load_to_google_storage
[2023-01-02T16:45:29.125+0000] {warnings.py:110} WARNING - /home/***/.local/lib/python3.7/site-packages/***/configuration.py:545: DeprecationWarning: The sql_alchemy_conn option in [core] has been moved to the sql_alchemy_conn option in [database] - the old setting has been used, but please update your config.
  option = self._get_environment_variables(deprecated_key, deprecated_section, key, section)

[2023-01-02T16:45:30.002+0000] {task_command.py:376} INFO - Running <TaskInstance: dpt_cosmetic.transaction.load_to_google_storage scheduled__2023-01-01T00:00:00+00:00 [running]> on host 703acec1b71e
[2023-01-02T16:45:30.402+0000] {taskinstance.py:1592} INFO - Exporting the following env vars:
AIRFLOW_CTX_DAG_OWNER=***
AIRFLOW_CTX_DAG_ID=dpt_cosmetic
AIRFLOW_CTX_TASK_ID=transaction.load_to_google_storage
AIRFLOW_CTX_EXECUTION_DATE=2023-01-01T00:00:00+00:00
AIRFLOW_CTX_TRY_NUMBER=1
AIRFLOW_CTX_DAG_RUN_ID=scheduled__2023-01-01T00:00:00+00:00
[2023-01-02T16:45:30.407+0000] {connection.py:429} ERROR - Unable to retrieve connection from secrets backend (EnvironmentVariablesBackend). Checking subsequent secrets backend.
Traceback (most recent call last):
  File "/home/airflow/.local/lib/python3.7/site-packages/airflow/models/connection.py", line 422, in get_connection_from_secrets
    conn = secrets_backend.get_connection(conn_id=conn_id)
  File "/home/airflow/.local/lib/python3.7/site-packages/airflow/secrets/base_secrets.py", line 115, in get_connection
    return self.deserialize_connection(conn_id=conn_id, value=value)
  File "/home/airflow/.local/lib/python3.7/site-packages/airflow/secrets/base_secrets.py", line 67, in deserialize_connection
    return Connection.from_json(conn_id=conn_id, value=value)
  File "/home/airflow/.local/lib/python3.7/site-packages/airflow/models/connection.py", line 449, in from_json
    return Connection(conn_id=conn_id, **kwargs)
TypeError: __init__() got an unexpected keyword argument 'key_path'
[2023-01-02T16:45:30.449+0000] {base.py:71} INFO - Using connection ID 'google_cloud_default' for task execution.
[2023-01-02T16:45:39.100+0000] {gcs.py:518} INFO - File /opt/***/storage/transaction/2023-01-03.csv uploaded to storage/transaction/2023-01-03.csv in ***_test_sd2beatles bucket
[2023-01-02T16:45:39.102+0000] {operator.py:28} INFO - successfully fetch the file,transaction
[2023-01-02T16:45:39.165+0000] {taskinstance.py:1406} INFO - Marking task as SUCCESS. dag_id=dpt_cosmetic, task_id=transaction.load_to_google_storage, execution_date=20230101T000000, start_date=20230102T164528, end_date=20230102T164539
[2023-01-02T16:45:39.297+0000] {local_task_job.py:164} INFO - Task exited with return code 0
[2023-01-02T16:45:39.381+0000] {local_task_job.py:273} INFO - 0 downstream tasks scheduled from follow-on schedule check
